Workbook

Sheet Descuadres por cliente
A1: Transportes Araya Franquiz
A2: Facturas donde el importe cobrado de la ficha no cuadra con la suma de sus cobros
A3: Listado a 21/09/2026 · 36 facturas de 27 clientes
A5: Para que sirve: en cada una de estas facturas hay dos cifras de lo cobrado que no coinciden. Una es la casilla "importe cobrado" de la ficha de la factura; la otra es lo que suman los cobros anotados uno a uno. Hay que decidir cual de las dos es la buena. Escribe tu decision en las dos ultimas columnas, las amarillas.
A6: Ojo: esto NO infla la deuda del panel. El informe de pendientes se queda con la mayor de las dos cifras, asi que nadie aparece debiendo de mas por esto. Lo que si hace es enganar a lo que lea la casilla a pelo.
A8: Cliente | B8: CIF | C8: Factura | D8: Fecha | E8: Estado | F8: Estado en Factusol | G8: Total | H8: Importe cobrado (ficha) | I8: Cobros anotados | J8: Diferencia | K8: Nº cobros | L8: Primer cobro | M8: Ultimo cobro | N8: Pendiente en el panel | O8: Que le pasa | P8: Cual es el bueno | Q8: Notas
A9: ALEGRANZA.S-L | B9: B-35511484
C10: 190734 | D10: 43769 | E10: Cobrada | F10: 2 Cobrada | G10: 8942.83 | H10: 8942.83 | I10: 1942.83 | J10: =I10-H10 | K10: 2 | L10: 43867 | M10: 44505 | N10: =G10-MAX(H10,I10) | O10: Faltan cobros por anotar, o la columna se quedo por encima
F11: Suma de ALEGRANZA.S-L | G11: =SUM(G10:G10) | H11: =SUM(H10:H10) | I11: =SUM(I10:I10) | J11: =SUM(J10:J10)
A13: Andreas Wenger, | B13: Y7798675X.
C14: 230469 | D14: 45138 | E14: Cobrada | F14: 2 Cobrada | G14: 206.43 | H14: 206.43 | I14: 175.1 | J14: =I14-H14 | K14: 1 | L14: 44957 | M14: 44957 | N14: =G14-MAX(H14,I14) | O14: Faltan cobros por anotar, o la columna se quedo por encima
F15: Suma de Andreas Wenger, | G15: =SUM(G14:G14) | H15: =SUM(H14:H14) | I15: =SUM(I14:I14) | J15: =SUM(J14:J14)
A17: ANTIGUACONTROL SOCIEDAD LIMITADA (ALISIOS) CONTROL MAX | B17: b76318351
C18: 210810 | D18: 44540 | E18: Cobrada | F18: 2 Cobrada | G18: 5974 | H18: 5974 | I18: 2987 | J18: =I18-H18 | K18: 1 | L18: 44540 | M18: 44540 | N18: =G18-MAX(H18,I18) | O18: La columna dice justo el doble de lo que suman los cobros
F19: Suma de ANTIGUACONTROL SOCIEDAD LIMITADA (ALISIOS) CONTROL MAX | G19: =SUM(G18:G18) | H19: =SUM(H18:H18) | I19: =SUM(I18:I18) | J19: =SUM(J18:J18)
A21: BLUE DOLPHIN HOTEL OPERATING AND ADMINISTRATION FUERTEVENTURA, S.L. | B21: B86677333
C22: 200197 | D22: 43921 | E22: Cobrada | F22: 2 Cobrada | G22: 1349.22 | H22: 1349.22 | I22: 1278.56 | J22: =I22-H22 | K22: 1 | L22: 44015 | M22: 44015 | N22: =G22-MAX(H22,I22) | O22: Faltan cobros por anotar, o la columna se quedo por encima
C23: 230729 | D23: 45230 | E23: Cobrada | F23: 2 Cobrada | G23: 1944.4 | H23: 1944.4 | I23: 1941.83 | J23: =I23-H23 | K23: 1 | L23: 45251 | M23: 45251 | N23: =G23-MAX(H23,I23) | O23: Faltan cobros por anotar, o la columna se quedo por encima
F24: Suma de BLUE DOLPHIN HOTEL OPERATING AND ADMINISTRATION FUERTEVENTURA, S.L. | G24: =SUM(G22:G23) | H24: =SUM(H22:H23) | I24: =SUM(I22:I23) | J24: =SUM(J22:J23)
A26: CANARAGUA CONCESIONES, S.A.U | B26: A76624345
C27: 190222 | D27: 43555 | E27: Cobrada | F27: 2 Cobrada | G27: 2548.87 | H27: 2548.87 | I27: 1449.54 | J27: =I27-H27 | K27: 1 | L27: 43658 | M27: 43658 | N27: =G27-MAX(H27,I27) | O27: Faltan cobros por anotar, o la columna se quedo por encima
C28: 200029 | D28: 43861 | E28: Cobrada | F28: 2 Cobrada | G28: 321.56 | H28: 321.56 | I28: 321.02 | J28: =I28-H28 | K28: 1 | L28: 43895 | M28: 43895 | N28: =G28-MAX(H28,I28) | O28: Faltan cobros por anotar, o la columna se quedo por encima
C29: 200069 | D29: 43871 | E29: Cobrada | F29: 2 Cobrada | G29: 147.4 | H29: 147.4 | I29: 147 | J29: =I29-H29 | K29: 1 | L29: 43895 | M29: 43895 | N29: =G29-MAX(H29,I29) | O29: Faltan cobros por anotar, o la columna se quedo por encima
F30: Suma de CANARAGUA CONCESIONES, S.A.U | G30: =SUM(G27:G29) | H30: =SUM(H27:H29) | I30: =SUM(I27:I29) | J30: =SUM(J27:J29)
A32: CLOE LORENZO S.L | B32: B76370667
C33: 210644 | D33: 44474 | E33: Pendiente | F33: 1 Cobro parcial | G33: 9246.2 | H33: 0 | I33: 2169.49 | J33: =I33-H33 | K33: 3 | L33: 44497 | M33: 44524 | N33: =G33-MAX(H33,I33) | O33: La columna esta a cero pero si hay cobros anotados
F34: Suma de CLOE LORENZO S.L | G34: =SUM(G33:G33) | H34: =SUM(H33:H33) | I34: =SUM(I33:I33) | J34: =SUM(J33:J33)
A36: CLUB MISTRAL FUERTEVENTURA, S.L.
C37: 3429 | D37: 42978 | E37: Cobrada | F37: 2 Cobrada | G37: 264 | H37: 264 | I37: 198 | J37: =I37-H37 | K37: 1 | L37: 42985 | M37: 42985 | N37: =G37-MAX(H37,I37) | O37: Faltan cobros por anotar, o la columna se quedo por encima
F38: Suma de CLUB MISTRAL FUERTEVENTURA, S.L. | G38: =SUM(G37:G37) | H38: =SUM(H37:H37) | I38: =SUM(I37:I37) | J38: =SUM(J37:J37)
A40: ECOLOGIA Y CONSTRUCCION FESUMAR SL | B40: B76055839
C41: 220664 | D41: 44804 | E41: Cobrada | F41: 2 Cobrada | G41: 36080.36 | H41: 36080.36 | I41: 35344.79 | J41: =I41-H41 | K41: 1 | L41: 44829 | M41: 44829 | N41: =G41-MAX(H41,I41) | O41: Faltan cobros por anotar, o la columna se quedo por encima
F42: Suma de ECOLOGIA Y CONSTRUCCION FESUMAR SL | G42: =SUM(G41:G41) | H42: =SUM(H41:H41) | I42: =SUM(I41:I41) | J42: =SUM(J41:J41)
A44: ECOTRANS 2000, S.L. | B44: B38626073
C45: 190529 | D45: 43707 | E45: Cobrada | F45: 2 Cobrada | G45: 32209.39 | H45: 32209.39 | I45: 23909.16 | J45: =I45-H45 | K45: 2 | L45: 43728 | M45: 43732 | N45: =G45-MAX(H45,I45) | O45: Faltan cobros por anotar, o la columna se quedo por encima
F46: Suma de ECOTRANS 2000, S.L. | G46: =SUM(G45:G45) | H46: =SUM(H45:H45) | I46: =SUM(I45:I45) | J46: =SUM(J45:J45)
A48: EL CAMILO COSILN, S.L | B48: B76190701
C49: 3749 | D49: 43126 | E49: Cobrada | F49: 2 Cobrada | G49: 580.89 | H49: 580.89 | I49: 0.8 | J49: =I49-H49 | K49: 1 | L49: 43126 | M49: 43126 | N49: =G49-MAX(H49,I49) | O49: Faltan cobros por anotar, o la columna se quedo por encima
F50: Suma de EL CAMILO COSILN, S.L | G50: =SUM(G49:G49) | H50: =SUM(H49:H49) | I50: =SUM(I49:I49) | J50: =SUM(J49:J49)
A52: ELITEPLAC, S.L.U | B52: B76280031
...

Sheet Resumen por cliente
A1: Resumen por cliente
A2: Cuantas facturas descuadran en cada cliente y por cuanto. Se calcula solo desde la otra hoja.
A4: Cliente | B4: Facturas | C4: Total facturado | D4: Importe cobrado (ficha) | E4: Cobros anotados | F4: Diferencia
A5: ALEGRANZA.S-L | B5: =COUNTA('Descuadres por cliente'!$C$10:$C$10) | C5: =SUM('Descuadres por cliente'!$G$10:$G$10) | D5: =SUM('Descuadres por cliente'!$H$10:$H$10) | E5: =SUM('Descuadres por cliente'!$I$10:$I$10) | F5: =E5-D5
A6: Andreas Wenger, | B6: =COUNTA('Descuadres por cliente'!$C$14:$C$14) | C6: =SUM('Descuadres por cliente'!$G$14:$G$14) | D6: =SUM('Descuadres por cliente'!$H$14:$H$14) | E6: =SUM('Descuadres por cliente'!$I$14:$I$14) | F6: =E6-D6
A7: ANTIGUACONTROL SOCIEDAD LIMITADA (ALISIOS) CONTROL MAX | B7: =COUNTA('Descuadres por cliente'!$C$18:$C$18) | C7: =SUM('Descuadres por cliente'!$G$18:$G$18) | D7: =SUM('Descuadres por cliente'!$H$18:$H$18) | E7: =SUM('Descuadres por cliente'!$I$18:$I$18) | F7: =E7-D7
A8: BLUE DOLPHIN HOTEL OPERATING AND ADMINISTRATION FUERTEVENTURA, S.L. | B8: =COUNTA('Descuadres por cliente'!$C$22:$C$23) | C8: =SUM('Descuadres por cliente'!$G$22:$G$23) | D8: =SUM('Descuadres por cliente'!$H$22:$H$23) | E8: =SUM('Descuadres por cliente'!$I$22:$I$23) | F8: =E8-D8
A9: CANARAGUA CONCESIONES, S.A.U | B9: =COUNTA('Descuadres por cliente'!$C$27:$C$29) | C9: =SUM('Descuadres por cliente'!$G$27:$G$29) | D9: =SUM('Descuadres por cliente'!$H$27:$H$29) | E9: =SUM('Descuadres por cliente'!$I$27:$I$29) | F9: =E9-D9
A10: CLOE LORENZO S.L | B10: =COUNTA('Descuadres por cliente'!$C$33:$C$33) | C10: =SUM('Descuadres por cliente'!$G$33:$G$33) | D10: =SUM('Descuadres por cliente'!$H$33:$H$33) | E10: =SUM('Descuadres por cliente'!$I$33:$I$33) | F10: =E10-D10
A11: CLUB MISTRAL FUERTEVENTURA, S.L. | B11: =COUNTA('Descuadres por cliente'!$C$37:$C$37) | C11: =SUM('Descuadres por cliente'!$G$37:$G$37) | D11: =SUM('Descuadres por cliente'!$H$37:$H$37) | E11: =SUM('Descuadres por cliente'!$I$37:$I$37) | F11: =E11-D11
A12: ECOLOGIA Y CONSTRUCCION FESUMAR SL | B12: =COUNTA('Descuadres por cliente'!$C$41:$C$41) | C12: =SUM('Descuadres por cliente'!$G$41:$G$41) | D12: =SUM('Descuadres por cliente'!$H$41:$H$41) | E12: =SUM('Descuadres por cliente'!$I$41:$I$41) | F12: =E12-D12
A13: ECOTRANS 2000, S.L. | B13: =COUNTA('Descuadres por cliente'!$C$45:$C$45) | C13: =SUM('Descuadres por cliente'!$G$45:$G$45) | D13: =SUM('Descuadres por cliente'!$H$45:$H$45) | E13: =SUM('Descuadres por cliente'!$I$45:$I$45) | F13: =E13-D13
A14: EL CAMILO COSILN, S.L | B14: =COUNTA('Descuadres por cliente'!$C$49:$C$49) | C14: =SUM('Descuadres por cliente'!$G$49:$G$49) | D14: =SUM('Descuadres por cliente'!$H$49:$H$49) | E14: =SUM('Descuadres por cliente'!$I$49:$I$49) | F14: =E14-D14
A15: ELITEPLAC, S.L.U | B15: =COUNTA('Descuadres por cliente'!$C$53:$C$53) | C15: =SUM('Descuadres por cliente'!$G$53:$G$53) | D15: =SUM('Descuadres por cliente'!$H$53:$H$53) | E15: =SUM('Descuadres por cliente'!$I$53:$I$53) | F15: =E15-D15
A16: FAUSTINO | B16: =COUNTA('Descuadres por cliente'!$C$57:$C$57) | C16: =SUM('Descuadres por cliente'!$G$57:$G$57) | D16: =SUM('Descuadres por cliente'!$H$57:$H$57) | E16: =SUM('Descuadres por cliente'!$I$57:$I$57) | F16: =E16-D16
A17: FERPASOL S.L | B17: =COUNTA('Descuadres por cliente'!$C$61:$C$61) | C17: =SUM('Descuadres por cliente'!$G$61:$G$61) | D17: =SUM('Descuadres por cliente'!$H$61:$H$61) | E17: =SUM('Descuadres por cliente'!$I$61:$I$61) | F17: =E17-D17
A18: FUERTECASA GRUPO INMOBILIARIO SOCIEDAD LIMITADA | B18: =COUNTA('Descuadres por cliente'!$C$65:$C$66) | C18: =SUM('Descuadres por cliente'!$G$65:$G$66) | D18: =SUM('Descuadres por cliente'!$H$65:$H$66) | E18: =SUM('Descuadres por cliente'!$I$65:$I$66) | F18: =E18-D18
A19: GEFUER SOCIEDAD LIMITADA | B19: =COUNTA('Descuadres por cliente'!$C$70:$C$70) | C19: =SUM('Descuadres por cliente'!$G$70:$G$70) | D19: =SUM('Descuadres por cliente'!$H$70:$H$70) | E19: =SUM('Descuadres por cliente'!$I$70:$I$70) | F19: =E19-D19
A20: GEOTECNIA PERFORACIONES DOMINGUEZ, S.L | B20: =COUNTA('Descuadres por cliente'!$C$74:$C$74) | C20: =SUM('Descuadres por cliente'!$G$74:$G$74) | D20: =SUM('Descuadres por cliente'!$H$74:$H$74) | E20: =SUM('Descuadres por cliente'!$I$74:$I$74) | F20: =E20-D20
A21: GRUPO SUPERIOR DE FORMACION CANARIAS SL | B21: =COUNTA('Descuadres por cliente'!$C$78:$C$78) | C21: =SUM('Descuadres por cliente'!$G$78:$G$78) | D21: =SUM('Descuadres por cliente'!$H$78:$H$78) | E21: =SUM('Descuadres por cliente'!$I$78:$I$78) | F21: =E21-D21
A22: HORPAVI 3000, S.L | B22: =COUNTA('Descuadres por cliente'!$C$82:$C$82) | C22: =SUM('Descuadres por cliente'!$G$82:$G$82) | D22: =SUM('Descuadres por cliente'!$H$82:$H$82) | E22: =SUM('Descuadres por cliente'!$I$82:$I$82) | F22: =E22-D22
A23: LUPIDOS MANAGENMENT, S.L. | B23: =COUNTA('Descuadres por cliente'!$C$86:$C$87) | C23: =SUM('Descuadres por cliente'!$G$86:$G$87) | D23: =SUM('Descuadres por cliente'!$H$86:$H$87) | E23: =SUM('Descuadres por cliente'!$I$86:$I$87) | F23: =E23-D23
A24: OBRAS PUBLICAS CANARIAS, S.L OPC | B24: =COUNTA('Descuadres por cliente'!$C$91:$C$91) | C24: =SUM('Descuadres por cliente'!$G$91:$G$91) | D24: =SUM('Descuadres por cliente'!$H$91:$H$91) | E24: =SUM('Descuadres por cliente'!$I$91:$I$91) | F24: =E24-D24
A25: PLAYAS DE JANDIA SA | B25: =COUNTA('Descuadres por cliente'!$C$95:$C$98) | C25: =SUM('Descuadres por cliente'!$G$95:$G$98) | D25: =SUM('Descuadres por cliente'!$H$95:$H$98) | E25: =SUM('Descuadres por cliente'!$I$95:$I$98) | F25: =E25-D25
A26: PREFABRICADOS MARTIN BRITO S.L | B26: =COUNTA('Descuadres por cliente'!$C$102:$C$102) | C26: =SUM('Descuadres por cliente'!$G$102:$G$102) | D26: =SUM('Descuadres por cliente'!$H$102:$H$102) | E26: =SUM('Descuadres por cliente'!$I$102:$I$102) | F26: =E26-D26
A27: RANCHO JANDIA, S.L. | B27: =COUNTA('Descuadres por cliente'!$C$106:$C$106) | C27: =SUM('Descuadres por cliente'!$G$106:$G$106) | D27: =SUM('Descuadres por cliente'!$H$106:$H$106) | E27: =SUM('Descuadres por cliente'!$I$106:$I$106) | F27: =E27-D27
A28: RODRIGUEZ LOPEZ ALTAVISTA, S.L. | B28: =COUNTA('Descuadres por cliente'!$C$110:$C$111) | C28: =SUM('Descuadres por cliente'!$G$110:$G$111) | D28: =SUM('Descuadres por cliente'!$H$110:$H$111) | E28: =SUM('Descuadres por cliente'!$I$110:$I$111) | F28: =E28-D28
A29: SOLYMAR BEACH | B29: =COUNTA('Descuadres por cliente'!$C$115:$C$115) | C29: =SUM('Descuadres por cliente'!$G$115:$G$115) | D29: =SUM('Descuadres por cliente'!$H$115:$H$115) | E29: =SUM('Descuadres por cliente'!$I$115:$I$115) | F29: =E29-D29
A30: STEFAN SCHOLZ. | B30: =COUNTA('Descuadres por cliente'!$C$119:$C$119) | C30: =SUM('Descuadres por cliente'!$G$119:$G$119) | D30: =SUM('Descuadres por cliente'!$H$119:$H$119) | E30: =SUM('Descuadres por cliente'!$I$119:$I$119) | F30: =E30-D30
A31: ZERO DID, S.L | B31: =COUNTA('Descuadres por cliente'!$C$123:$C$123) | C31: =SUM('Descuadres por cliente'!$G$123:$G$123) | D31: =SUM('Descuadres por cliente'!$H$123:$H$123) | E31: =SUM('Descuadres por cliente'!$I$123:$I$123) | F31: =E31-D31
A32: TOTAL | B32: =SUM(B5:B31) | C32: =SUM(C5:C31) | D32: =SUM(D5:D31) | E32: =SUM(E5:E31) | F32: =SUM(F5:F31)

Sheet Como leerlo
A1: Como leer este listado
A3: Que es esto
B4: Cada factura de aqui tiene dos cifras de lo cobrado que no coinciden: la casilla "importe cobrado" de su ficha, y lo que suman los cobros anotados uno a uno. Hay que decidir cual es la buena.
A6: Donde escribes tu
B7: En las dos columnas amarillas de la otra hoja: "Cual es el bueno" (con desplegable) y "Notas". El resto no hay que tocarlo.
A9: Las opciones del desplegable
A10: La casilla de la ficha | B10: La cifra buena es la de la ficha. Entonces faltan cobros por anotar en el panel.
A11: Los cobros anotados | B11: La cifra buena es la suma de los cobros. Entonces hay que corregir la casilla de la ficha.
A12: Hay cobros sin anotar | B12: Se cobro de verdad, pero ese cobro no llego nunca al panel. Hay que meterlo con su fecha.
A13: Es confirming o factoring | B13: El dinero entro por el banco de otra manera y por eso no hay cobro anotado.
A14: Otra cosa - ver notas | B14: Cualquier otro caso. Explicalo en la columna de Notas.
A16: Lo que NO pasa
B17: Esto no hace que nadie aparezca debiendo de mas. El informe de pendientes de cobro se queda siempre con la mayor de las dos cifras, asi que la deuda que ves es la buena. El descuadre solo enganya a lo que lea la casilla directamente, como le paso al expediente de HUBARA el 21/09/2026.
A19: De donde sale
B20: De la base del panel, el 21/09/2026: facturas_venta.importe_cobrado frente a la suma de la tabla cobros. Se sacaron las que se diferencian en mas de un centimo y tienen al menos un cobro anotado.
